<?xml version="1.0" ?>
<!-- =================================================================================== -->
<!-- |    This document was autogenerated by xacro from cart_pole.urdf.xacro           | -->
<!-- |    EDITING THIS FILE BY HAND IS NOT RECOMMENDED                                 | -->
<!-- =================================================================================== -->
<robot name="cart_pole">
  <!-- =============== Link & Joint =============== -->
  <!-- Base -->
  <link name="base_footprint"/>
  <joint name="base_link_joint" type="fixed">
    <origin xyz="0 0 0"/>
    <parent link="base_footprint"/>
    <child link="base_link"/>
  </joint>
  <link name="base_link">
    <visual>
      <geometry>
        <mesh filename="package://robot_description/meshes/DAE/base/stand.dae"/>
      </geometry>
    </visual>
    <collision>
      <geometry>
        <mesh filename="package://robot_description/meshes/STL/base/stand.stl"/>
      </geometry>
    </collision>
    <inertial>
      <origin xyz="0 0 -0.333"/>
      <mass value="88"/>
      <inertia ixx="14.25" ixy="0" ixz="0.0245" iyy="78.78" iyz="0" izz="64.57"/>
    </inertial>
  </link>
  <joint name="cart_joint" type="prismatic">
    <origin rpy="0 0 0" xyz="0 0 0"/>
    <parent link="base_link"/>
    <child link="cart_link"/>
    <limit effort="30" lower="-1.0" upper="1.0" velocity="10"/>
    <dynamics damping="0.005" friction="0.1"/>
    <axis xyz="1 0 0"/>
  </joint>
  <link name="cart_link">
    <visual>
      <geometry>
        <mesh filename="package://robot_description/meshes/DAE/cart/cart.dae"/>
      </geometry>
    </visual>
    <collision>
      <geometry>
        <mesh filename="package://robot_description/meshes/STL/cart/cart.stl"/>
      </geometry>
    </collision>
    <inertial>
      <origin xyz="0 0 0"/>
      <mass value="2.7"/>
      <inertia ixx="0.005878" ixy="0" ixz="0" iyy="0.01145" iyz="0" izz="0.01186"/>
    </inertial>
  </link>
  <joint name="pole_joint" type="revolute">
    <origin rpy="0 3.14159274 0" xyz="0 0.1 0"/>
    <parent link="cart_link"/>
    <child link="pole_link"/>
    <limit effort="15" lower="-1.7" upper="1.7" velocity="10"/>
    <dynamics damping="0.00001" friction="0.01"/>
    <axis xyz="0 1 0"/>
  </joint>
  <link name="pole_link">
    <visual>
      <geometry>
        <mesh filename="package://robot_description/meshes/DAE/pole/pole.dae"/>
      </geometry>
    </visual>
    <collision>
      <geometry>
        <mesh filename="package://robot_description/meshes/STL/pole/pole.stl"/>
      </geometry>
    </collision>
    <inertial>
      <origin xyz="0 0 -0.489554"/>
      <mass value="0.85955"/>
      <inertia ixx="0.07508" ixy="0" ixz="-0.0000095" iyy="0.07574" iyz="0" izz="0.0007851"/>
    </inertial>
  </link>
  <joint name="tip_joint" type="revolute">
    <origin rpy="0 0 0" xyz="0 0 -1"/>
    <parent link="pole_link"/>
    <child link="tip_link"/>
    <limit effort="30" lower="-1.0" upper="1.0" velocity="10"/>
    <dynamics damping="0.005" friction="0.1"/>
    <axis xyz="0 1 0"/>
  </joint>
  <link name="tip_link">
    <inertial>
      <origin xyz="0 0 0"/>
      <mass value="0.0001"/>
      <inertia ixx="0.00000001" ixy="0" ixz="0" iyy="0.00000001" iyz="0" izz="0.00000001"/>
    </inertial>
  </link>
  <transmission name="cart_trans">
    <type>transmission_interface/SimpleTransmission</type>
    <joint name="cart_joint">
      <hardwareInterface>hardware_interface/EffortJointInterface</hardwareInterface>
    </joint>
    <actuator name="cart_motor">
      <hardwareInterface>hardware_interface/EffortJointInterface</hardwareInterface>
      <mechanicalReduction>1</mechanicalReduction>
    </actuator>
  </transmission>
  <!-- =============== Gazebo =============== -->
  <gazebo>
    <plugin filename="libgazebo_ros_control.so" name="gazebo_ros_control"/>
  </gazebo>
  <gazebo reference="base_link">
    <selfCollide>false</selfCollide>
    <mu1 value="0.05"/>
    <mu2 value="0.05"/>
  </gazebo>
  <gazebo reference="cart_link">
    <selfCollide>false</selfCollide>
    <mu1 value="1.2"/>
    <mu2 value="1.2"/>
  </gazebo>
  <gazebo reference="pole_link">
    <selfCollide>false</selfCollide>
    <mu1 value="1.2"/>
    <mu2 value="1.2"/>
  </gazebo>
  <gazebo reference="tip_link">
    <selfCollide>false</selfCollide>
    <mu1 value="1.2"/>
    <mu2 value="1.2"/>
  </gazebo>
</robot>
